[2018-11-02T10:23:02.416] [ERROR] dateFileLog - { Error: ER_DUP_ENTRY: Duplicate entry 'STD-0000-00000000-0-0-0-0-0-daPres_ChargeBackB' for key 'UniqueA'
    at Query.Sequence._packetToError (D:\work\Source\node_modules\mysql\lib\protocol\sequences\Sequence.js:48:14)
    at Query.ErrorPacket (D:\work\Source\node_modules\mysql\lib\protocol\sequences\Query.js:82:18)
    at Protocol._parsePacket (D:\work\Source\node_modules\mysql\lib\protocol\Protocol.js:271:23)
    at Parser.write (D:\work\Source\node_modules\mysql\lib\protocol\Parser.js:77:12)
    at Protocol.write (D:\work\Source\node_modules\mysql\lib\protocol\Protocol.js:39:16)
    at Socket.<anonymous> (D:\work\Source\node_modules\mysql\lib\Connection.js:82:28)
    at emitOne (events.js:116:13)
    at Socket.emit (events.js:211:7)
    at addChunk (_stream_readable.js:263:12)
    at readableAddChunk (_stream_readable.js:250:11)
    --------------------
    at Protocol._enqueue (D:\work\Source\node_modules\mysql\lib\protocol\Protocol.js:135:48)
    at PoolConnection.Connection.query (D:\work\Source\node_modules\mysql\lib\Connection.js:185:25)
    at doQuery (D:\work\Source\yujiang.Foil.Node\src\yjDBService.engine.mysql.js:474:24)
    at success (D:\work\Source\yujiang.Foil.Node\src\yjDBService.engine.mysql.js:465:9)
    at Object.exports.safeSuccess (D:\work\Source\yujiang.Foil.Node\src\yjError.js:94:13)
    at Object.exports.handleResult (D:\work\Source\yujiang.Foil.Node\src\yjError.js:148:12)
    at D:\work\Source\yujiang.Foil.Node\src\yjDBService.engine.mysql.js:89:11
    at Ping.onPing (D:\work\Source\node_modules\mysql\lib\Pool.js:94:5)
    at bound (domain.js:301:14)
    at Ping.runBound [as _callback] (domain.js:314:12)
  code: 'ER_DUP_ENTRY',
  errno: 1062,
  sqlState: '23000',
  index: 0,
  sql: 'INSERT INTO hmiprint_moni (Manufacturer,Prec,CtrlType,MachType,DDKey,CN,TW,EN,Visb,Reserved0,Reserved1,Reserved2,Reserved3,Reserved4) VALUES (?,?,?,?,?,?,?,?,?,?,?,?,?,?)' }
[2018-11-02T10:23:02.423] [ERROR] dateFileLog - Error: ER_DUP_ENTRY: Duplicate entry 'STD-0000-00000000-0-0-0-0-0-daPres_ChargeBackB' for key 'UniqueA'
    at D:\work\Source\yujiang.Foil.Node\src\yjREST.engine.remote.superagent.js:43:34
    at Request.callback (D:\work\Source\node_modules\superagent\lib\node\index.js:797:3)
    at IncomingMessage.<anonymous> (D:\work\Source\node_modules\superagent\lib\node\index.js:990:12)
    at emitNone (events.js:111:20)
    at IncomingMessage.emit (events.js:208:7)
    at endReadableNT (_stream_readable.js:1064:12)
    at _combinedTickCallback (internal/process/next_tick.js:139:11)
    at process._tickDomainCallback (internal/process/next_tick.js:219:9)
[2018-11-02T13:00:51.610] [ERROR] dateFileLog - { Error: ER_BAD_FIELD_ERROR: Unknown column 'Prec' in 'field list'
    at Query.Sequence._packetToError (D:\work\Source\node_modules\mysql\lib\protocol\sequences\Sequence.js:48:14)
    at Query.ErrorPacket (D:\work\Source\node_modules\mysql\lib\protocol\sequences\Query.js:82:18)
    at Protocol._parsePacket (D:\work\Source\node_modules\mysql\lib\protocol\Protocol.js:271:23)
    at Parser.write (D:\work\Source\node_modules\mysql\lib\protocol\Parser.js:77:12)
    at Protocol.write (D:\work\Source\node_modules\mysql\lib\protocol\Protocol.js:39:16)
    at Socket.<anonymous> (D:\work\Source\node_modules\mysql\lib\Connection.js:82:28)
    at emitOne (events.js:116:13)
    at Socket.emit (events.js:211:7)
    at addChunk (_stream_readable.js:263:12)
    at readableAddChunk (_stream_readable.js:250:11)
    --------------------
    at Protocol._enqueue (D:\work\Source\node_modules\mysql\lib\protocol\Protocol.js:135:48)
    at PoolConnection.Connection.query (D:\work\Source\node_modules\mysql\lib\Connection.js:185:25)
    at doQuery (D:\work\Source\yujiang.Foil.Node\src\yjDBService.engine.mysql.js:474:24)
    at success (D:\work\Source\yujiang.Foil.Node\src\yjDBService.engine.mysql.js:465:9)
    at Object.exports.safeSuccess (D:\work\Source\yujiang.Foil.Node\src\yjError.js:94:13)
    at Object.exports.handleResult (D:\work\Source\yujiang.Foil.Node\src\yjError.js:148:12)
    at D:\work\Source\yujiang.Foil.Node\src\yjDBService.engine.mysql.js:89:11
    at Ping.onPing (D:\work\Source\node_modules\mysql\lib\Pool.js:94:5)
    at bound (domain.js:301:14)
    at Ping.runBound [as _callback] (domain.js:314:12)
  code: 'ER_BAD_FIELD_ERROR',
  errno: 1054,
  sqlState: '42S22',
  index: 0,
  sql: ' WITH info AS  (        SELECT DataID FROM hmiprint_mold        WHERE Manufacturer=? AND CtrlType=? AND MachType=?        AND Reserved0=? AND Reserved1=? AND Reserved2=? AND Reserved3=? AND Reserved4=?  )  SELECT DataID, Component, Block, Unit, Label, CN, Prec, Visb FROM hmiprint_mold        WHERE DataID NOT IN ( SELECT DataID FROM info )            AND Manufacturer=? AND CtrlType=? AND MachType=?            AND Reserved0=? AND Reserved1=? AND Reserved2=? AND Reserved3=? AND Reserved4=?  UNION ALL  SELECT DataID, Component, Block, Unit, Label, CN, Prec, Visb FROM hmiprint_mold        WHERE Manufacturer=? AND CtrlType=? AND MachType=?        AND Reserved0=? AND Reserved1=? AND Reserved2=? AND Reserved3=? AND Reserved4=? ' }
[2018-11-02T13:00:51.613] [ERROR] dateFileLog - Error: ER_BAD_FIELD_ERROR: Unknown column 'Prec' in 'field list'
    at D:\work\Source\yujiang.Foil.Node\src\yjREST.engine.remote.superagent.js:43:34
    at Request.callback (D:\work\Source\node_modules\superagent\lib\node\index.js:797:3)
    at IncomingMessage.<anonymous> (D:\work\Source\node_modules\superagent\lib\node\index.js:990:12)
    at emitNone (events.js:111:20)
    at IncomingMessage.emit (events.js:208:7)
    at endReadableNT (_stream_readable.js:1064:12)
    at _combinedTickCallback (internal/process/next_tick.js:139:11)
    at process._tickDomainCallback (internal/process/next_tick.js:219:9)
[2018-11-02T13:04:29.975] [ERROR] dateFileLog - Error: Password is not correct for userAID HMIUser.
    at callback_getUser (D:\work\Source\yujiang.Foil.Node.BizServer\biz\account\checkLogin.js:178:24)
    at D:\work\Source\yujiang.Foil.Node\src\yjError.js:129:4
    at Object.exports.safeSuccess (D:\work\Source\yujiang.Foil.Node\src\yjError.js:94:13)
    at Object.exports.safeCallback (D:\work\Source\yujiang.Foil.Node\src\yjError.js:128:11)
    at Object.exports.handleResult (D:\work\Source\yujiang.Foil.Node\src\yjError.js:142:11)
    at Query.<anonymous> (D:\work\Source\yujiang.Foil.Node\src\yjDBService.engine.mysql.js:564:33)
    at bound (domain.js:301:14)
    at Query.runBound [as _callback] (domain.js:314:12)
    at Query.Sequence.end (D:\work\Source\node_modules\mysql\lib\protocol\sequences\Sequence.js:96:24)
    at Query._handleFinalResultPacket (D:\work\Source\node_modules\mysql\lib\protocol\sequences\Query.js:143:8)
[2018-11-02T13:04:29.977] [ERROR] dateFileLog - Error: Password is not correct for userAID HMIUser.
    at D:\work\Source\yujiang.Foil.Node\src\yjREST.engine.remote.superagent.js:43:34
    at Request.callback (D:\work\Source\node_modules\superagent\lib\node\index.js:797:3)
    at IncomingMessage.<anonymous> (D:\work\Source\node_modules\superagent\lib\node\index.js:990:12)
    at emitNone (events.js:111:20)
    at IncomingMessage.emit (events.js:208:7)
    at endReadableNT (_stream_readable.js:1064:12)
    at _combinedTickCallback (internal/process/next_tick.js:139:11)
    at process._tickDomainCallback (internal/process/next_tick.js:219:9)
