[2018-12-05T09:10:13.401] [ERROR] dateFileLog - { Error: ER_DUP_ENTRY: Duplicate entry 'test' for key 'UNIQUE'
    at Query.Sequence._packetToError (D:\work\TOOLSWEB\node_modules\mysql\lib\protocol\sequences\Sequence.js:48:14)
    at Query.ErrorPacket (D:\work\TOOLSWEB\node_modules\mysql\lib\protocol\sequences\Query.js:82:18)
    at Protocol._parsePacket (D:\work\TOOLSWEB\node_modules\mysql\lib\protocol\Protocol.js:271:23)
    at Parser.write (D:\work\TOOLSWEB\node_modules\mysql\lib\protocol\Parser.js:77:12)
    at Protocol.write (D:\work\TOOLSWEB\node_modules\mysql\lib\protocol\Protocol.js:39:16)
    at Socket.<anonymous> (D:\work\TOOLSWEB\node_modules\mysql\lib\Connection.js:82:28)
    at emitOne (events.js:116:13)
    at Socket.emit (events.js:211:7)
    at addChunk (_stream_readable.js:263:12)
    at readableAddChunk (_stream_readable.js:250:11)
    --------------------
    at Protocol._enqueue (D:\work\TOOLSWEB\node_modules\mysql\lib\protocol\Protocol.js:135:48)
    at PoolConnection.Connection.query (D:\work\TOOLSWEB\node_modules\mysql\lib\Connection.js:185:25)
    at doQuery (D:\work\TOOLSWEB\yujiang.Foil.Node\src\yjDBService.engine.mysql.js:474:24)
    at success (D:\work\TOOLSWEB\yujiang.Foil.Node\src\yjDBService.engine.mysql.js:465:9)
    at Object.exports.safeSuccess (D:\work\TOOLSWEB\yujiang.Foil.Node\src\yjError.js:94:13)
    at Object.exports.handleResult (D:\work\TOOLSWEB\yujiang.Foil.Node\src\yjError.js:148:12)
    at D:\work\TOOLSWEB\yujiang.Foil.Node\src\yjDBService.engine.mysql.js:89:11
    at Ping.onPing (D:\work\TOOLSWEB\node_modules\mysql\lib\Pool.js:94:5)
    at bound (domain.js:301:14)
    at Ping.runBound [as _callback] (domain.js:314:12)
  code: 'ER_DUP_ENTRY',
  errno: 1062,
  sqlState: '23000',
  index: 0,
  sql: ' update `Processes` set `ProcessAID`=?,`Name`=?,`Hidden`=? where `ProcessOID`=?' }
[2018-12-05T09:10:13.405] [ERROR] dateFileLog - Error: ER_DUP_ENTRY: Duplicate entry 'test' for key 'UNIQUE'
    at D:\work\TOOLSWEB\yujiang.Foil.Node\src\yjREST.engine.remote.superagent.js:43:34
    at Request.callback (D:\work\TOOLSWEB\node_modules\superagent\lib\node\index.js:797:3)
    at IncomingMessage.<anonymous> (D:\work\TOOLSWEB\node_modules\superagent\lib\node\index.js:990:12)
    at emitNone (events.js:111:20)
    at IncomingMessage.emit (events.js:208:7)
    at endReadableNT (_stream_readable.js:1064:12)
    at _combinedTickCallback (internal/process/next_tick.js:139:11)
    at process._tickDomainCallback (internal/process/next_tick.js:219:9)
[2018-12-05T10:50:52.970] [ERROR] dateFileLog - [ { Error: [Microsoft][SQL Server Native Client 11.0]命名管道提供程序: 无法打开与 SQL Server 的连接 [53].  sqlstate: '08001', code: 53 },
  { Error: [Microsoft][SQL Server Native Client 11.0]登录超时已过期 sqlstate: 'HYT00', code: 0 },
  { Error: [Microsoft][SQL Server Native Client 11.0]与 SQL Server 建立连接时发生了与网络相关的或特定于实例的错误。找不到或无法访问服务器。请检查实例名称是否正确以及 SQL Server 是否配置为允许远程连接。有关详细信息，请参阅 SQL Server 联机丛书。 sqlstate: '08001', code: 53 } ]
[2018-12-05T17:00:00.279] [ERROR] dateFileLog - { Error: ER_BAD_FIELD_ERROR: Unknown column 'PKValue' in 'field list'
    at Query.Sequence._packetToError (D:\work\TOOLSWEB\node_modules\mysql\lib\protocol\sequences\Sequence.js:48:14)
    at Query.ErrorPacket (D:\work\TOOLSWEB\node_modules\mysql\lib\protocol\sequences\Query.js:82:18)
    at Protocol._parsePacket (D:\work\TOOLSWEB\node_modules\mysql\lib\protocol\Protocol.js:271:23)
    at Parser.write (D:\work\TOOLSWEB\node_modules\mysql\lib\protocol\Parser.js:77:12)
    at Protocol.write (D:\work\TOOLSWEB\node_modules\mysql\lib\protocol\Protocol.js:39:16)
    at Socket.<anonymous> (D:\work\TOOLSWEB\node_modules\mysql\lib\Connection.js:82:28)
    at emitOne (events.js:116:13)
    at Socket.emit (events.js:211:7)
    at addChunk (_stream_readable.js:263:12)
    at readableAddChunk (_stream_readable.js:250:11)
    --------------------
    at Protocol._enqueue (D:\work\TOOLSWEB\node_modules\mysql\lib\protocol\Protocol.js:135:48)
    at PoolConnection.Connection.query (D:\work\TOOLSWEB\node_modules\mysql\lib\Connection.js:185:25)
    at doQuery (D:\work\TOOLSWEB\yujiang.Foil.Node\src\yjDBService.engine.mysql.js:474:24)
    at success (D:\work\TOOLSWEB\yujiang.Foil.Node\src\yjDBService.engine.mysql.js:465:9)
    at Object.exports.safeSuccess (D:\work\TOOLSWEB\yujiang.Foil.Node\src\yjError.js:94:13)
    at Object.exports.handleResult (D:\work\TOOLSWEB\yujiang.Foil.Node\src\yjError.js:148:12)
    at D:\work\TOOLSWEB\yujiang.Foil.Node\src\yjDBService.engine.mysql.js:89:11
    at Ping.onPing [as _callback] (D:\work\TOOLSWEB\node_modules\mysql\lib\Pool.js:94:5)
    at Ping.Sequence.end (D:\work\TOOLSWEB\node_modules\mysql\lib\protocol\sequences\Sequence.js:96:24)
    at Ping.Sequence.OkPacket (D:\work\TOOLSWEB\node_modules\mysql\lib\protocol\sequences\Sequence.js:105:8)
  code: 'ER_BAD_FIELD_ERROR',
  errno: 1054,
  sqlState: '42S22',
  index: 0,
  sql: 'insert into erpdb (PKValue) values(?)' }
[2018-12-05T17:04:08.854] [ERROR] dateFileLog - { Error: ER_BAD_FIELD_ERROR: Unknown column 'PKValue' in 'field list'
    at Query.Sequence._packetToError (D:\work\TOOLSWEB\node_modules\mysql\lib\protocol\sequences\Sequence.js:48:14)
    at Query.ErrorPacket (D:\work\TOOLSWEB\node_modules\mysql\lib\protocol\sequences\Query.js:82:18)
    at Protocol._parsePacket (D:\work\TOOLSWEB\node_modules\mysql\lib\protocol\Protocol.js:271:23)
    at Parser.write (D:\work\TOOLSWEB\node_modules\mysql\lib\protocol\Parser.js:77:12)
    at Protocol.write (D:\work\TOOLSWEB\node_modules\mysql\lib\protocol\Protocol.js:39:16)
    at Socket.<anonymous> (D:\work\TOOLSWEB\node_modules\mysql\lib\Connection.js:82:28)
    at emitOne (events.js:116:13)
    at Socket.emit (events.js:211:7)
    at addChunk (_stream_readable.js:263:12)
    at readableAddChunk (_stream_readable.js:250:11)
    --------------------
    at Protocol._enqueue (D:\work\TOOLSWEB\node_modules\mysql\lib\protocol\Protocol.js:135:48)
    at PoolConnection.Connection.query (D:\work\TOOLSWEB\node_modules\mysql\lib\Connection.js:185:25)
    at doQuery (D:\work\TOOLSWEB\yujiang.Foil.Node\src\yjDBService.engine.mysql.js:474:24)
    at success (D:\work\TOOLSWEB\yujiang.Foil.Node\src\yjDBService.engine.mysql.js:465:9)
    at Object.exports.safeSuccess (D:\work\TOOLSWEB\yujiang.Foil.Node\src\yjError.js:94:13)
    at Object.exports.handleResult (D:\work\TOOLSWEB\yujiang.Foil.Node\src\yjError.js:148:12)
    at D:\work\TOOLSWEB\yujiang.Foil.Node\src\yjDBService.engine.mysql.js:89:11
    at Ping.onPing [as _callback] (D:\work\TOOLSWEB\node_modules\mysql\lib\Pool.js:94:5)
    at Ping.Sequence.end (D:\work\TOOLSWEB\node_modules\mysql\lib\protocol\sequences\Sequence.js:96:24)
    at Ping.Sequence.OkPacket (D:\work\TOOLSWEB\node_modules\mysql\lib\protocol\sequences\Sequence.js:105:8)
  code: 'ER_BAD_FIELD_ERROR',
  errno: 1054,
  sqlState: '42S22',
  index: 0,
  sql: 'insert into erpdb (PKValue) values(?)' }
[2018-12-05T17:04:09.801] [ERROR] dateFileLog - { Error: ER_BAD_FIELD_ERROR: Unknown column 'PKValue' in 'field list'
    at Query.Sequence._packetToError (D:\work\TOOLSWEB\node_modules\mysql\lib\protocol\sequences\Sequence.js:48:14)
    at Query.ErrorPacket (D:\work\TOOLSWEB\node_modules\mysql\lib\protocol\sequences\Query.js:82:18)
    at Protocol._parsePacket (D:\work\TOOLSWEB\node_modules\mysql\lib\protocol\Protocol.js:271:23)
    at Parser.write (D:\work\TOOLSWEB\node_modules\mysql\lib\protocol\Parser.js:77:12)
    at Protocol.write (D:\work\TOOLSWEB\node_modules\mysql\lib\protocol\Protocol.js:39:16)
    at Socket.<anonymous> (D:\work\TOOLSWEB\node_modules\mysql\lib\Connection.js:82:28)
    at emitOne (events.js:116:13)
    at Socket.emit (events.js:211:7)
    at addChunk (_stream_readable.js:263:12)
    at readableAddChunk (_stream_readable.js:250:11)
    --------------------
    at Protocol._enqueue (D:\work\TOOLSWEB\node_modules\mysql\lib\protocol\Protocol.js:135:48)
    at PoolConnection.Connection.query (D:\work\TOOLSWEB\node_modules\mysql\lib\Connection.js:185:25)
    at doQuery (D:\work\TOOLSWEB\yujiang.Foil.Node\src\yjDBService.engine.mysql.js:474:24)
    at success (D:\work\TOOLSWEB\yujiang.Foil.Node\src\yjDBService.engine.mysql.js:465:9)
    at Object.exports.safeSuccess (D:\work\TOOLSWEB\yujiang.Foil.Node\src\yjError.js:94:13)
    at Object.exports.handleResult (D:\work\TOOLSWEB\yujiang.Foil.Node\src\yjError.js:148:12)
    at D:\work\TOOLSWEB\yujiang.Foil.Node\src\yjDBService.engine.mysql.js:89:11
    at Ping.onPing [as _callback] (D:\work\TOOLSWEB\node_modules\mysql\lib\Pool.js:94:5)
    at Ping.Sequence.end (D:\work\TOOLSWEB\node_modules\mysql\lib\protocol\sequences\Sequence.js:96:24)
    at Ping.Sequence.OkPacket (D:\work\TOOLSWEB\node_modules\mysql\lib\protocol\sequences\Sequence.js:105:8)
  code: 'ER_BAD_FIELD_ERROR',
  errno: 1054,
  sqlState: '42S22',
  index: 0,
  sql: 'insert into erpdb (PKValue) values(?)' }
[2018-12-05T17:04:10.801] [ERROR] dateFileLog - { Error: ER_BAD_FIELD_ERROR: Unknown column 'PKValue' in 'field list'
    at Query.Sequence._packetToError (D:\work\TOOLSWEB\node_modules\mysql\lib\protocol\sequences\Sequence.js:48:14)
    at Query.ErrorPacket (D:\work\TOOLSWEB\node_modules\mysql\lib\protocol\sequences\Query.js:82:18)
    at Protocol._parsePacket (D:\work\TOOLSWEB\node_modules\mysql\lib\protocol\Protocol.js:271:23)
    at Parser.write (D:\work\TOOLSWEB\node_modules\mysql\lib\protocol\Parser.js:77:12)
    at Protocol.write (D:\work\TOOLSWEB\node_modules\mysql\lib\protocol\Protocol.js:39:16)
    at Socket.<anonymous> (D:\work\TOOLSWEB\node_modules\mysql\lib\Connection.js:82:28)
    at emitOne (events.js:116:13)
    at Socket.emit (events.js:211:7)
    at addChunk (_stream_readable.js:263:12)
    at readableAddChunk (_stream_readable.js:250:11)
    --------------------
    at Protocol._enqueue (D:\work\TOOLSWEB\node_modules\mysql\lib\protocol\Protocol.js:135:48)
    at PoolConnection.Connection.query (D:\work\TOOLSWEB\node_modules\mysql\lib\Connection.js:185:25)
    at doQuery (D:\work\TOOLSWEB\yujiang.Foil.Node\src\yjDBService.engine.mysql.js:474:24)
    at success (D:\work\TOOLSWEB\yujiang.Foil.Node\src\yjDBService.engine.mysql.js:465:9)
    at Object.exports.safeSuccess (D:\work\TOOLSWEB\yujiang.Foil.Node\src\yjError.js:94:13)
    at Object.exports.handleResult (D:\work\TOOLSWEB\yujiang.Foil.Node\src\yjError.js:148:12)
    at D:\work\TOOLSWEB\yujiang.Foil.Node\src\yjDBService.engine.mysql.js:89:11
    at Ping.onPing [as _callback] (D:\work\TOOLSWEB\node_modules\mysql\lib\Pool.js:94:5)
    at Ping.Sequence.end (D:\work\TOOLSWEB\node_modules\mysql\lib\protocol\sequences\Sequence.js:96:24)
    at Ping.Sequence.OkPacket (D:\work\TOOLSWEB\node_modules\mysql\lib\protocol\sequences\Sequence.js:105:8)
  code: 'ER_BAD_FIELD_ERROR',
  errno: 1054,
  sqlState: '42S22',
  index: 0,
  sql: 'insert into erpdb (PKValue) values(?)' }
[2018-12-05T17:04:11.797] [ERROR] dateFileLog - { Error: ER_BAD_FIELD_ERROR: Unknown column 'PKValue' in 'field list'
    at Query.Sequence._packetToError (D:\work\TOOLSWEB\node_modules\mysql\lib\protocol\sequences\Sequence.js:48:14)
    at Query.ErrorPacket (D:\work\TOOLSWEB\node_modules\mysql\lib\protocol\sequences\Query.js:82:18)
    at Protocol._parsePacket (D:\work\TOOLSWEB\node_modules\mysql\lib\protocol\Protocol.js:271:23)
    at Parser.write (D:\work\TOOLSWEB\node_modules\mysql\lib\protocol\Parser.js:77:12)
    at Protocol.write (D:\work\TOOLSWEB\node_modules\mysql\lib\protocol\Protocol.js:39:16)
    at Socket.<anonymous> (D:\work\TOOLSWEB\node_modules\mysql\lib\Connection.js:82:28)
    at emitOne (events.js:116:13)
    at Socket.emit (events.js:211:7)
    at addChunk (_stream_readable.js:263:12)
    at readableAddChunk (_stream_readable.js:250:11)
    --------------------
    at Protocol._enqueue (D:\work\TOOLSWEB\node_modules\mysql\lib\protocol\Protocol.js:135:48)
    at PoolConnection.Connection.query (D:\work\TOOLSWEB\node_modules\mysql\lib\Connection.js:185:25)
    at doQuery (D:\work\TOOLSWEB\yujiang.Foil.Node\src\yjDBService.engine.mysql.js:474:24)
    at success (D:\work\TOOLSWEB\yujiang.Foil.Node\src\yjDBService.engine.mysql.js:465:9)
    at Object.exports.safeSuccess (D:\work\TOOLSWEB\yujiang.Foil.Node\src\yjError.js:94:13)
    at Object.exports.handleResult (D:\work\TOOLSWEB\yujiang.Foil.Node\src\yjError.js:148:12)
    at D:\work\TOOLSWEB\yujiang.Foil.Node\src\yjDBService.engine.mysql.js:89:11
    at Ping.onPing [as _callback] (D:\work\TOOLSWEB\node_modules\mysql\lib\Pool.js:94:5)
    at Ping.Sequence.end (D:\work\TOOLSWEB\node_modules\mysql\lib\protocol\sequences\Sequence.js:96:24)
    at Ping.Sequence.OkPacket (D:\work\TOOLSWEB\node_modules\mysql\lib\protocol\sequences\Sequence.js:105:8)
  code: 'ER_BAD_FIELD_ERROR',
  errno: 1054,
  sqlState: '42S22',
  index: 0,
  sql: 'insert into erpdb (PKValue) values(?)' }
[2018-12-05T17:04:12.798] [ERROR] dateFileLog - { Error: ER_BAD_FIELD_ERROR: Unknown column 'PKValue' in 'field list'
    at Query.Sequence._packetToError (D:\work\TOOLSWEB\node_modules\mysql\lib\protocol\sequences\Sequence.js:48:14)
    at Query.ErrorPacket (D:\work\TOOLSWEB\node_modules\mysql\lib\protocol\sequences\Query.js:82:18)
    at Protocol._parsePacket (D:\work\TOOLSWEB\node_modules\mysql\lib\protocol\Protocol.js:271:23)
    at Parser.write (D:\work\TOOLSWEB\node_modules\mysql\lib\protocol\Parser.js:77:12)
    at Protocol.write (D:\work\TOOLSWEB\node_modules\mysql\lib\protocol\Protocol.js:39:16)
    at Socket.<anonymous> (D:\work\TOOLSWEB\node_modules\mysql\lib\Connection.js:82:28)
    at emitOne (events.js:116:13)
    at Socket.emit (events.js:211:7)
    at addChunk (_stream_readable.js:263:12)
    at readableAddChunk (_stream_readable.js:250:11)
    --------------------
    at Protocol._enqueue (D:\work\TOOLSWEB\node_modules\mysql\lib\protocol\Protocol.js:135:48)
    at PoolConnection.Connection.query (D:\work\TOOLSWEB\node_modules\mysql\lib\Connection.js:185:25)
    at doQuery (D:\work\TOOLSWEB\yujiang.Foil.Node\src\yjDBService.engine.mysql.js:474:24)
    at success (D:\work\TOOLSWEB\yujiang.Foil.Node\src\yjDBService.engine.mysql.js:465:9)
    at Object.exports.safeSuccess (D:\work\TOOLSWEB\yujiang.Foil.Node\src\yjError.js:94:13)
    at Object.exports.handleResult (D:\work\TOOLSWEB\yujiang.Foil.Node\src\yjError.js:148:12)
    at D:\work\TOOLSWEB\yujiang.Foil.Node\src\yjDBService.engine.mysql.js:89:11
    at Ping.onPing [as _callback] (D:\work\TOOLSWEB\node_modules\mysql\lib\Pool.js:94:5)
    at Ping.Sequence.end (D:\work\TOOLSWEB\node_modules\mysql\lib\protocol\sequences\Sequence.js:96:24)
    at Ping.Sequence.OkPacket (D:\work\TOOLSWEB\node_modules\mysql\lib\protocol\sequences\Sequence.js:105:8)
  code: 'ER_BAD_FIELD_ERROR',
  errno: 1054,
  sqlState: '42S22',
  index: 0,
  sql: 'insert into erpdb (PKValue) values(?)' }
[2018-12-05T17:18:44.405] [ERROR] dateFileLog - { Error: [Microsoft][ODBC 驱动程序管理器] 未发现数据源名称并且未指定默认驱动程序 sqlstate: 'IM002', code: 0 }
[2018-12-05T17:18:45.385] [ERROR] dateFileLog - { Error: [Microsoft][ODBC 驱动程序管理器] 未发现数据源名称并且未指定默认驱动程序 sqlstate: 'IM002', code: 0 }
[2018-12-05T17:18:46.384] [ERROR] dateFileLog - { Error: [Microsoft][ODBC 驱动程序管理器] 未发现数据源名称并且未指定默认驱动程序 sqlstate: 'IM002', code: 0 }
[2018-12-05T17:18:47.385] [ERROR] dateFileLog - { Error: [Microsoft][ODBC 驱动程序管理器] 未发现数据源名称并且未指定默认驱动程序 sqlstate: 'IM002', code: 0 }
[2018-12-05T17:18:48.386] [ERROR] dateFileLog - { Error: [Microsoft][ODBC 驱动程序管理器] 未发现数据源名称并且未指定默认驱动程序 sqlstate: 'IM002', code: 0 }
[2018-12-05T17:29:08.699] [ERROR] dateFileLog - { Error: connect ETIMEDOUT
    at PoolConnection.Connection._handleConnectTimeout (D:\work\TOOLSWEB\node_modules\mysql\lib\Connection.js:346:13)
    at Object.onceWrapper (events.js:313:30)
    at emitNone (events.js:106:13)
    at Socket.emit (events.js:208:7)
    at Socket._onTimeout (net.js:422:8)
    at ontimeout (timers.js:498:11)
    at tryOnTimeout (timers.js:323:5)
    at Timer.listOnTimeout (timers.js:290:5)
    --------------------
    at Protocol._enqueue (D:\work\TOOLSWEB\node_modules\mysql\lib\protocol\Protocol.js:135:48)
    at Protocol.handshake (D:\work\TOOLSWEB\node_modules\mysql\lib\protocol\Protocol.js:52:41)
    at PoolConnection.connect (D:\work\TOOLSWEB\node_modules\mysql\lib\Connection.js:109:18)
    at Pool.getConnection (D:\work\TOOLSWEB\node_modules\mysql\lib\Pool.js:45:23)
    at getConnection (D:\work\TOOLSWEB\yujiang.Foil.Node\src\yjDBService.engine.mysql.js:81:12)
    at Object.exec (D:\work\TOOLSWEB\yujiang.Foil.Node\src\yjDBService.engine.mysql.js:462:7)
    at Object.getOrgs (D:\work\TOOLSWEB\yujiang.Foil.Node.BizServer\biz\org\processAuthority\processAuthority.db.mysql.js:6:15)
    at buildOrgs (D:\work\TOOLSWEB\yujiang.Foil.Node.BizServer\biz\org\processAuthority.js:69:5)
    at fn (D:\work\TOOLSWEB\node_modules\async\lib\async.js:641:34)
    at Immediate._onImmediate (D:\work\TOOLSWEB\node_modules\async\lib\async.js:557:34)
  errorno: 'ETIMEDOUT',
  code: 'ETIMEDOUT',
  syscall: 'connect',
  fatal: true }
